/Users/zander/.rvm/rubies/ruby-1.9.3-p448/lib/ruby/1.9.1/drb/drb.rb:736:in `rescue in block in open': druby://127.0.0.1:9876 - #<Errno::ECONNREFUSED: Connection refused - connect(2)> (DRb::DRbConnError)
        from /Users/zander/.rvm/rubies/ruby-1.9.3-p448/lib/ruby/1.9.1/drb/drb.rb:730:in `block in open'
        from /Users/zander/.rvm/rubies/ruby-1.9.3-p448/lib/ruby/1.9.1/drb/drb.rb:729:in `each'
        from /Users/zander/.rvm/rubies/ruby-1.9.3-p448/lib/ruby/1.9.1/drb/drb.rb:729:in `open'
        from /Users/zander/.rvm/rubies/ruby-1.9.3-p448/lib/ruby/1.9.1/drb/drb.rb:1191:in `initialize'
        from /Users/zander/.rvm/rubies/ruby-1.9.3-p448/lib/ruby/1.9.1/drb/drb.rb:1171:in `new'
        from /Users/zander/.rvm/rubies/ruby-1.9.3-p448/lib/ruby/1.9.1/drb/drb.rb:1171:in `open'
        from /Users/zander/.rvm/rubies/ruby-1.9.3-p448/lib/ruby/1.9.1/drb/drb.rb:1087:in `block in method_missing'
        from /Users/zander/.rvm/rubies/ruby-1.9.3-p448/lib/ruby/1.9.1/drb/drb.rb:1105:in `with_friend'
        from /Users/zander/.rvm/rubies/ruby-1.9.3-p448/lib/ruby/1.9.1/drb/drb.rb:1086:in `method_missing'
        from /Users/zander/source/teapot/vendor/ruby/1.9.1/gems/pry-remote-0.1.8/lib/pry-remote.rb:289:in `run'
        from /Users/zander/source/teapot/vendor/ruby/1.9.1/gems/pry-remote-0.1.8/bin/pry-remote:4:in `<top (required)>'
        from /Users/zander/source/teapot/vendor/ruby/1.9.1/bin/pry-remote:23:in `load'
        from /Users/zander/source/teapot/vendor/ruby/1.9.1/bin/pry-remote:23:in `<main>'
